Workbook

Sheet Sheet4
A1: product_merch_classification2 | B1: product_merch_classification3 | C1: product_category_level1 | D1: product_category_level2 | E1: product_category_level3 | F1: parent_product_part_number | G1: product_part_number | H1: product_name | I1: Code | J1: vendor_name | K1: vendor_purchaser_code | L1: Purchase MOQ | M1: Master Case Pack | N1: Case Pk CBM | O1: Final Buy Qty | P1: Vendor Earliest ETD
A2: Bowls & Feeders | B2: Storage & Accessories | C2: Dog | D2: Bowls & Feeders | E2: Storage & Accessories | F2: 242555 | G2: 215996 | H2: Frisco Silicone Pet Food Can Cover, 2 Pack | I2: P18545 | J2: SUPER DESIGN MANUFACTURE CO ., LTD ZHUHAI | K2: MWILSON | L2: 528 | M2: 48 | N2: 0.0106 | O2: 11568 | P2: ASAP
A3: Beds & Furniture | B3: Furniture | C3: Cat | D3: Beds, Crates & Gear | E3: Furniture | F3: 155161 | G3: 128075 | H3: Frisco 33-in Heavy Duty Sisal Cat Scratching Post, Cream | I3: 3755 | J3: HANGZHOU TIANYUAN PET PRODUCTS CO., LTD. | K3: JADESCHACK | L3: 100 | M3: 1 | N3: 0.0409605 | O3: 10252 | P3: ASAP
A4: Technology | B4: Consumables & Accessories | C4: Dog | D4: Bowls & Feeders | E4: Filters | F4: 396587 | G4: 370373 | H4: Filter Foam Replacement Filter for Drinkwell Lotus, Avalon, Pagoda, Sedona & 360 Stainless Steel Dog & Cat Water Fountains, 2 count | I4: 3722 | J4: JIANG SU ZHONG HENG PET ARTICLES JOINT-STOCK CO. | K4: KNGO1 | L4: 1080 | M4: 120 | N4: 0.083420437 | O4: 4920 | P4: ASAP
A5: Beds & Furniture | B5: Furniture | C5: Cat | D5: Beds, Crates & Gear | E5: Furniture | F5: 155161 | G5: 128079 | H5: Frisco 33-in Heavy Duty Sisal Cat Scratching Post, Brown | I5: 3755 | J5: HANGZHOU TIANYUAN PET PRODUCTS CO., LTD. | K5: JADESCHACK | L5: 100 | M5: 1 | N5: 0.0409605 | O5: 4159 | P5: ASAP
A6: Leashes, Collars & Harnesses | B6: Harnesses | C6: Dog | D6: Leashes & Collars | E6: Harnesses | F6: 304271 | G6: 277874 | H6: Frisco Basic No Pull Harness, Black/Gray, LG | I6: P000544 | J6: SHANGHAI SENFUL CO LTD | K6: JADESCHACK | L6: 560 | M6: 80 | N6: 0.057612505 | O6: 560 | P6: ASAP
A7: Beds & Furniture | B7: Furniture | C7: Cat | D7: Beds, Crates & Gear | E7: Furniture | F7: 155161 | G7: 163749 | H7: Frisco 33-in Heavy Duty Sisal Cat Scratching Post, Gray | I7: 3755 | J7: HANGZHOU TIANYUAN PET PRODUCTS CO., LTD. | K7: JADESCHACK | L7: 100 | M7: 1 | N7: 0.0409605 | O7: 3991 | P7: ASAP
A8: Beds & Furniture | B8: Beds | C8: Cat | D8: Beds, Crates & Gear | E8: Beds | F8: 171680 | G8: 144826 | H8: Frisco Sherpa Reversible Cat Mat, Light Gray Basket Weave Print | I8: B000064 | J8: PM&J LLC - DIRECT IMPORT | K8: JADESCHACK | L8: 288 | M8: 72 | N8: 0.50540491 | O8: 3888 | P8: ASAP
A9: Leashes, Collars & Harnesses | B9: Harnesses | C9: Dog | D9: Leashes & Collars | E9: Harnesses | F9: 304271 | G9: 277879 | H9: Frisco Basic No Pull Harness, Navy/Blue, LG | I9: P000544 | J9: SHANGHAI SENFUL CO LTD | K9: JADESCHACK | L9: 560 | M9: 80 | N9: 0.057612505 | O9: 560 | P9: ASAP
A10: Waste Management | B10: Poop Bags | C10: Dog | D10: Waste Management | E10: Poop Bags | F10: 336123 | G10: 309822 | H10: Frisco Dog Poop Bag Solid Assortment in Teal Blue, Violet, Gray, & Coral, 270 count | I10: 3722 | J10: JIANG SU ZHONG HENG PET ARTICLES JOINT-STOCK CO. | K10: KNGO1 | L10: 504 | M10: 24 | N10: 0.0406848 | O10: 1536 | P10: ASAP
A11: Litter Accessories | B11: Mats | C11: Cat | D11: Litter & Accessories | E11: Mats | F11: 193000 | G11: 166298 | H11: Frisco Rectangular Cat Litter Mat, Grey, Large | I11: 3722 | J11: JIANG SU ZHONG HENG PET ARTICLES JOINT-STOCK CO. | K11: KNGO1 | L11: 3000 | M11: 24 | N11: 0.098571 | O11: 3000 | P11: ASAP
A12: Waste Management | B12: Potty Pads & Diapers | C12: Dog | D12: Waste Management | E12: Potty Pads & Diapers | F12: 117279 | G12: 227482 | H12: Frisco Large Premium Dog Training & Potty Pads, 22 x 23-in, Unscented, 20 count | I12: 3722 | J12: JIANG SU ZHONG HENG PET ARTICLES JOINT-STOCK CO. | K12: KNGO1 | L12: 252 | M12: 12 | N12: 0.067363 | O12: 828 | P12: ASAP
A13: Bowls & Feeders | B13: Bowls & Diners | C13: Dog | D13: Bowls & Feeders | E13: Bowls & Diners | F13: 242575 | G13: 216017 | H13: Frisco Marble Print Stainless Steel Double Elevated Dog Bowl, Black Stand, Medium: 3 cup | I13: P18545 | J13: SUPER DESIGN MANUFACTURE CO ., LTD ZHUHAI | K13: MWILSON | L13: 500 | M13: 4 | N13: 0.09752688 | O13: 2400 | P13: ASAP
A14: Beds & Furniture | B14: Beds | C14: Cat | D14: Beds, Crates & Gear | E14: Beds | F14: 192019 | G14: 299466 | H14: Frisco Self-Warming Bolster Kitten Bed, Cream | I14: B000064 | J14: PM&J LLC - DIRECT IMPORT | K14: JADESCHACK | L14: 288 | M14: 48 | N14: 0.24402237 | O14: 2304 | P14: ASAP
A15: Leashes, Collars & Harnesses | B15: Leashes | C15: Dog | D15: Leashes & Collars | E15: Tie Outs | F15: 1016294 | G15: 1016302 | H15: Frisco Dog Tie-Out Stake | I15: 3722 | J15: JIANG SU ZHONG HENG PET ARTICLES JOINT-STOCK CO. | K15: KNGO1 | L15: 204 | M15: 6 | N15: 0.038325 | O15: 204 | P15: ASAP
A16: Leashes, Collars & Harnesses | B16: Collars | C16: Dog | D16: Leashes & Collars | E16: Collars | F16: 317910 | G16: 291560 | H16: Frisco Comfort Padded Dog Collar, Soft Beige Pink, X-Small | I16: B000064 | J16: PM&J LLC - DIRECT IMPORT | K16: JADESCHACK | L16: 500 | M16: 50 | N16: 0.004186 | O16: 500 | P16: ASAP
A17: Leashes, Collars & Harnesses | B17: Leashes | C17: Dog | D17: Leashes & Collars | E17: Tie Outs | F17: 193164 | G17: 166464 | H17: Frisco Easy Grip Spiral Stake, 18-in | I17: 3722 | J17: JIANG SU ZHONG HENG PET ARTICLES JOINT-STOCK CO. | K17: KNGO1 | L17: 204 | M17: 6 | N17: 0.00891 | O17: 708 | P17: ASAP
A18: Leashes, Collars & Harnesses | B18: Leashes | C18: Dog | D18: Leashes & Collars | E18: Tie Outs | F18: 193147 | G18: 166446 | H18: Frisco Easy Grip Stake with Tie Out Cable, Large, 15-ft | I18: 3722 | J18: JIANG SU ZHONG HENG PET ARTICLES JOINT-STOCK CO. | K18: KNGO1 | L18: 204 | M18: 6 | N18: 0.016038 | O18: 204 | P18: ASAP
A19: Leashes, Collars & Harnesses | B19: Leashes | C19: Dog | D19: Leashes & Collars | E19: Tie Outs | F19: 193147 | G19: 166447 | H19: Frisco Easy Grip Stake with Tie Out Cable, Large, 30-ft | I19: 3722 | J19: JIANG SU ZHONG HENG PET ARTICLES JOINT-STOCK CO. | K19: KNGO1 | L19: 204 | M19: 6 | N19: 0.0191565 | O19: 204 | P19: ASAP
A20: Bowls & Feeders | B20: Bowls & Diners | C20: Dog | D20: Bowls & Feeders | E20: Bowls & Diners | F20: 186593 | G20: 159867 | H20: Frisco Stainless Steel Bowl, 7 cup | I20: P000579 | J20: GO FETCH, LLC | K20: MWILSON | L20: 216 | M20: 1 | N20: 0.015928226 | O20: 1809 | P20: ASAP
A21: Bowls & Feeders | B21: Storage & Accessories | C21: Dog | D21: Bowls & Feeders | E21: Placemats | F21: 242552 | G21: 215993 | H21: Frisco Silicone Dog & Cat Food Mat, Gray, Medium | I21: P18545 | J21: SUPER DESIGN MANUFACTURE CO ., LTD ZHUHAI | K21: MWILSON | L21: 504 | M21: 36 | N21: 0.03340575 | O21: 1764 | P21: ASAP
A22: Beauty & Grooming | B22: Brushes & Combs | C22: Dog | D22: Grooming | E22: Brushes & Combs | F22: 233490 | G22: 206893 | H22: Frisco Deshedding Cat & Dog Brush, Medium, Medium to Long Hair | I22: P18360 | J22: PETENGREAT CO LTD | K22: JADESCHACK | L22: 720 | M22: 72 | N22: 0.033454204 | O22: 1656 | P22: ASAP
A23: Beds & Furniture | B23: Furniture | C23: Cat | D23: Beds, Crates & Gear | E23: Furniture | F23: 167085 | G23: 140149 | H23: Frisco 21-in Sisal Cat Scratching Post with Toy, Cream, 1 count | I23: 7701 | J23: TIANJIN QINGQUAN PET PRODUCTS CO. LTD | K23: JADESCHACK | L23: 100 | M23: 1 | N23: 0.009900155 | O23: 1639 | P23: ASAP
A24: Waste Management | B24: Poop Bags | C24: Dog | D24: Waste Management | E24: Poop Bags | F24: 162702 | G24: 135730 | H24: Frisco Refill Dog Poop Bags, Unscented, 900 count | I24: 3722 | J24: JIANG SU ZHONG HENG PET ARTICLES JOINT-STOCK CO. | K24: KNGO1 | L24: 500 | M24: 10 | N24: 0.05194 | O24: 500 | P24: ASAP
A25: Beds & Furniture | B25: Beds | C25: Dog | D25: Beds, Crates & Gear | E25: Beds | F25: 126783 | G25: 112088 | H25: Frisco Replacement Cover for Steel-Framed Elevated Dog Bed, Gray, M: 35.7-in L x 26.3-in W, 1 count | I25: 3722 | J25: JIANG SU ZHONG HENG PET ARTICLES JOINT-STOCK CO. | K25: KNGO1 | L25: 264 | M25: 24 | N25: 0.034398 | O25: 264 | P25: ASAP
A26: Beauty & Grooming | B26: Brushes & Combs | C26: Dog | D26: Grooming | E26: Brushes & Combs | F26: 233469 | G26: 206869 | H26: Frisco Soft Bristle Slicker Dog Brush, Small | I26: P18360 | J26: PETENGREAT CO LTD | K26: JADESCHACK | L26: 720 | M26: 72 | N26: 0.046959675 | O26: 1512 | P26: ASAP
A27: Leashes, Collars & Harnesses | B27: Leashes | C27: Dog | D27: Leashes & Collars | E27: Tie Outs | F27: 193136 | G27: 166437 | H27: Frisco Tie Out Cable, 15-ft | I27: 3722 | J27: JIANG SU ZHONG HENG PET ARTICLES JOINT-STOCK CO. | K27: KNGO1 | L27: 200 | M27: 5 | N27: 0.004698 | O27: 200 | P27: ASAP
A28: Leashes, Collars & Harnesses | B28: Collars | C28: Dog | D28: Leashes & Collars | E28: Collars | F28: 317910 | G28: 291572 | H28: Frisco Comfort Padded Dog Collar, True Navy, Large | I28: B000064 | J28: PM&J LLC - DIRECT IMPORT | K28: JADESCHACK | L28: 500 | M28: 50 | N28: 0.010166 | O28: 500 | P28: ASAP
A29: Leashes, Collars & Harnesses | B29: Leashes | C29: Dog | D29: Leashes & Collars | E29: Tie Outs | F29: 193136 | G29: 166438 | H29: Frisco Tie Out Cable, 20-ft | I29: 3722 | J29: JIANG SU ZHONG HENG PET ARTICLES JOINT-STOCK CO. | K29: KNGO1 | L29: 200 | M29: 5 | N29: 0.0066785 | O29: 200 | P29: ASAP
A30: Beds & Furniture | B30: Beds | C30: Cat | D30: Beds, Crates & Gear | E30: Beds | F30: 171680 | G30: 210253 | H30: Frisco Sherpa Reversible Cat Mat, Navy Herringbone | I30: B000064 | J30: PM&J LLC - DIRECT IMPORT | K30: JADESCHACK | L30: 288 | M30: 72 | N30: 0.50540491 | O30: 1440 | P30: ASAP
A31: Bowls & Feeders | B31: Storage & Accessories | C31: Dog | D31: Bowls & Feeders | E31: Storage & Accessories | F31: 258577 | G31: 232070 | H31: Frisco Melamine Dog & Cat Food Scoop with Bamboo Handle, 1 cup | I31: P18545 | J31: SUPER DESIGN MANUFACTURE CO ., LTD ZHUHAI | K31: MWILSON | L31: 504 | M31: 36 | N31: 0.05895981 | O31: 1404 | P31: ASAP
A32: Leashes, Collars & Harnesses | B32: Leashes | C32: Dog | D32: Leashes & Collars | E32: Tie Outs | F32: 193136 | G32: 166439 | H32: Frisco Tie Out Cable, 30-ft | I32: 3722 | J32: JIANG SU ZHONG HENG PET ARTICLES JOINT-STOCK CO. | K32: KNGO1 | L32: 200 | M32: 5 | N32: 0.0084942 | O32: 490 | P32: ASAP
A33: Leashes, Collars & Harnesses | B33: Leashes | C33: Dog | D33: Leashes & Collars | E33: Tie Outs | F33: 193136 | G33: 984598 | H33: Frisco Tie Out Cable, 40-ft | I33: 3722 | J33: JIANG SU ZHONG HENG PET ARTICLES JOINT-STOCK CO. | K33: KNGO1 | L33: 200 | M33: 4 | N33: 0.01204125 | O33: 704 | P33: ASAP
A34: Leashes, Collars & Harnesses | B34: Leashes | C34: Dog | D34: Leashes & Collars | E34: Tie Outs | F34: 193131 | G34: 166429 | H34: Frisco Tie Out Cable, Large, 15-ft | I34: 3722 | J34: JIANG SU ZHONG HENG PET ARTICLES JOINT-STOCK CO. | K34: KNGO1 | L34: 200 | M34: 8 | N34: 0.005301 | O34: 200 | P34: ASAP
A35: Leashes, Collars & Harnesses | B35: Harnesses | C35: Dog | D35: Leashes & Collars | E35: Harnesses | F35: 317889 | G35: 291545 | H35: Frisco Comfort Padded Dog Harness, Jet Black, Large | I35: B000064 | J35: PM&J LLC - DIRECT IMPORT | K35: JADESCHACK | L35: 504 | M35: 24 | N35: 0.03393 | O35: 504 | P35: ASAP
A36: Leashes, Collars & Harnesses | B36: Harnesses | C36: Dog | D36: Leashes & Collars | E36: Harnesses | F36: 317889 | G36: 291537 | H36: Frisco Comfort Padded Dog Harness, Malachite Green, Small | I36: B000064 | J36: PM&J LLC - DIRECT IMPORT | K36: JADESCHACK | L36: 480 | M36: 48 | N36: 0.042957 | O36: 480 | P36: ASAP
A37: Leashes, Collars & Harnesses | B37: Leashes | C37: Dog | D37: Leashes & Collars | E37: Leashes | F37: 317931 | G37: 291580 | H37: Frisco Comfort Padded Dog Leash, Faded Rose, Small | I37: B000064 | J37: PM&J LLC - DIRECT IMPORT | K37: JADESCHACK | L37: 500 | M37: 50 | N37: 0.012274 | O37: 500 | P37: ASAP
A38: Bowls & Feeders | B38: Bowls & Diners | C38: Dog | D38: Bowls & Feeders | E38: Bowls & Diners | F38: 258583 | G38: 232076 | H38: Frisco Square Melamine Dog & Cat Bowl Set with Bamboo Stand, Small: 2 cup | I38: P18545 | J38: SUPER DESIGN MANUFACTURE CO ., LTD ZHUHAI | K38: MWILSON | L38: 504 | M38: 6 | N38: 0.04142166 | O38: 1026 | P38: ASAP
A39: Leashes, Collars & Harnesses | B39: Leashes | C39: Dog | D39: Leashes & Collars | E39: Leashes | F39: 317931 | G39: 291579 | H39: Frisco Comfort Padded Dog Leash, Malachite Green, Small | I39: B000064 | J39: PM&J LLC - DIRECT IMPORT | K39: JADESCHACK | L39: 500 | M39: 50 | N39: 0.01227406 | O39: 500 | P39: ASAP
A40: Leashes, Collars & Harnesses | B40: Leashes | C40: Dog | D40: Leashes & Collars | E40: Leashes | F40: 317931 | G40: 291586 | H40: Frisco Comfort Padded Dog Leash, Soft Beige Pink, Medium | I40: B000064 | J40: PM&J LLC - DIRECT IMPORT | K40: JADESCHACK | L40: 500 | M40: 50 | N40: 0.01755 | O40: 500 | P40: ASAP
...

Sheet Sheet2
A1: product_merch_classification2 | B1: parent_product_part_number | C1: product_part_number | D1: product_name | E1: Code | F1: vendor_name | G1: vendor_purchaser_code | H1: Purchase MOQ | I1: Master Case Pack | J1: Case Pk CBM | K1: Final Buy Qty | L1: Vendor Earliest ETD | M1: WAIT
A2: Toys | B2: 201482 | C2: 308868 | D2: Frisco Step-In Cat Scratcher Toy with Catnip, Constellations | E2: P27093 | F2: SPORTPET DESIGNS LLC - PL | G2: KNGO1 | H2: 1500 | I2: 4 | J2: 0.067100049 | K2: 18024 | L2: 45992 | M2: =COUNTIF(Sheet6!C:C,Sheet2!C2) -> 0
A3: Toys | B3: 187916 | C3: 161196 | D3: Frisco Fabric Teaser Wand Cat Toy, Neon Bubbles | E3: P20837 | F3: KIDS FIRST ASIA CO LTD | G3: KNGO1 | H3: 1224 | I3: 72 | J3: 0.020976748 | K3: 15120 | L3: 45992 | M3: =COUNTIF(Sheet6!C:C,Sheet2!C3) -> 0
A4: Bowls & Feeders | B4: 242555 | C4: 215996 | D4: Frisco Silicone Pet Food Can Cover, 2 Pack | E4: P18545 | F4: SUPER DESIGN MANUFACTURE CO ., LTD ZHUHAI | G4: MWILSON | H4: 528 | I4: 48 | J4: 0.0106 | K4: 33504 | L4: 45992 | M4: =COUNTIF(Sheet6!C:C,Sheet2!C4) -> 0
A5: Waste Management | B5: 206849 | C5: 173778 | D5: Frisco Medium Dog Training & Potty Pads, 21 x 21-in, Unscented, 100 count | E5: P000486 | F5: TIANJIN YIYI HYGIENE PRODUCTS CO. LTD | G5: KNGO1 | H5: 800 | I5: 4 | J5: 0.059441431 | K5: 3392 | L5: 45992 | M5: =COUNTIF(Sheet6!C:C,Sheet2!C5) -> 0
A6: Toys | B6: 201428 | C6: 174739 | D6: Frisco Giraffe Bobberz Plush Squeaky Dog Toy, Large/X-Large | E6: P20837 | F6: KIDS FIRST ASIA CO LTD | G6: KNGO1 | H6: 1200 | I6: 24 | J6: 0.086946394 | K6: 5664 | L6: 45992 | M6: =COUNTIF(Sheet6!C:C,Sheet2!C6) -> 0
A7: Toys | B7: 201430 | C7: 174741 | D7: Frisco Llama Bobberz Plush Squeaky Dog Toy, Large/X-Large | E7: P20837 | F7: KIDS FIRST ASIA CO LTD | G7: KNGO1 | H7: 1200 | I7: 24 | J7: 0.086946394 | K7: 5352 | L7: 45992 | M7: =COUNTIF(Sheet6!C:C,Sheet2!C7) -> 0
A8: Toys | B8: 179577 | C8: 152801 | D8: Frisco Fetch Squeaky TPR Ball Dog Toy, Orange, Large, 1 count | E8: P20837 | F8: KIDS FIRST ASIA CO LTD | G8: KNGO1 | H8: 2016 | I8: 36 | J8: 0.034200886 | K8: 4788 | L8: 45992 | M8: =COUNTIF(Sheet6!C:C,Sheet2!C8) -> 0
A9: Beds & Furniture | B9: 126783 | C9: 99232 | D9: Frisco Replacement Cover for Steel-Framed Elevated Dog Bed, Brown, L: 43.7-in L x 32.4-in W, 1 count | E9: B3722 | F9: CAMBODIA JIANG SU ZHONG HENG PET ARTICLES JOINT-STOCK CO., | G9: KNGO1 | H9: 264 | I9: 24 | J9: 0.04941 | K9: 1776 | L9: 45992 | M9: =COUNTIF(Sheet6!C:C,Sheet2!C9) -> 0
A10: Toys | B10: 1073542 | C10: 1073550 | D10: Frisco Axolotl Variety Pack Cat Toy with Catnip, 4 count | E10: P20837 | F10: KIDS FIRST ASIA CO LTD | G10: KNGO1 | H10: 1224 | I10: 72 | J10: 0.059402983 | K10: 4464 | L10: 45992 | M10: =COUNTIF(Sheet6!C:C,Sheet2!C10) -> 0
A11: Waste Management | B11: 176632 | C11: 149818 | D11: Frisco Medium Dog Training & Potty Pads, 21 x 21-in, Floral Scented, 100 count | E11: P000486 | F11: TIANJIN YIYI HYGIENE PRODUCTS CO. LTD | G11: KNGO1 | H11: 800 | I11: 4 | J11: 0.064160009 | K11: 9484 | L11: 45992 | M11: =COUNTIF(Sheet6!C:C,Sheet2!C11) -> 0
A12: Beds & Furniture | B12: 126779 | C12: 99230 | D12: Frisco Steel-Framed Elevated Dog Bed, Brown, Large | E12: 3722 | F12: CAMBODIA JIANG SU ZHONG HENG PET ARTICLES JOINT-STOCK CO., | G12: KNGO1 | H12: 250 | I12: 5 | J12: 0.0636771 | K12: 3695 | L12: 45992 | M12: =COUNTIF(Sheet6!C:C,Sheet2!C12) -> 0
A13: Toys | B13: 179597 | C13: 233612 | D13: Frisco Bunny Bungee Plush Squeaky Dog Toy, Medium/Large | E13: P20837 | F13: KIDS FIRST ASIA CO LTD | G13: KNGO1 | H13: 1224 | I13: 36 | J13: 0.059401732 | K13: 1800 | L13: 45992 | M13: =COUNTIF(Sheet6!C:C,Sheet2!C13) -> 0
A14: Toys | B14: 201455 | C14: 174766 | D14: Frisco Trash Can & Raccoons Hide & Seek Puzzle Plush Squeaky Dog Toy Refills, Small/Medium, 3 count | E14: P20837 | F14: KIDS FIRST ASIA CO LTD | G14: KNGO1 | H14: 1200 | I14: 48 | J14: 0.059401636 | K14: 3984 | L14: 45992 | M14: =COUNTIF(Sheet6!C:C,Sheet2!C14) -> 0
A15: Toys | B15: 189547 | C15: 162836 | D15: Frisco Birthday Bear Plush Squeaky Dog Toy, Medium | E15: P20837 | F15: KIDS FIRST ASIA CO LTD | G15: KNGO1 | H15: 1224 | I15: 36 | J15: 0.071604928 | K15: 7056 | L15: 45992 | M15: =COUNTIF(Sheet6!C:C,Sheet2!C15) -> 0
A16: Toys | B16: 173847 | C16: 147013 | D16: Frisco Fox Plush Squeaky Dog Toy, Small/Medium | E16: P20837 | F16: KIDS FIRST ASIA CO LTD | G16: KNGO1 | H16: 1224 | I16: 36 | J16: 0.057601493 | K16: 3888 | L16: 45992 | M16: =COUNTIF(Sheet6!C:C,Sheet2!C16) -> 0
A17: Beds & Furniture | B17: 126779 | C17: 112076 | D17: Frisco Steel-Framed Elevated Dog Bed, Gray, Large | E17: B3722 | F17: CAMBODIA JIANG SU ZHONG HENG PET ARTICLES JOINT-STOCK CO., | G17: KNGO1 | H17: 250 | I17: 5 | J17: 0.0636771 | K17: 3155 | L17: 45992 | M17: =COUNTIF(Sheet6!C:C,Sheet2!C17) -> 0
A18: Waste Management | B18: 117279 | C18: 89561 | D18: Frisco Large Premium Dog Training & Potty Pads, 22 x 23-in, Unscented, 100 count | E18: 3722 | F18: JIANG SU ZHONG HENG PET ARTICLES JOINT-STOCK CO. | G18: KNGO1 | H18: 1500 | I18: 4 | J18: 0.102765 | K18: 5320 | L18: 45992 | M18: =COUNTIF(Sheet6!C:C,Sheet2!C18) -> 0
A19: Toys | B19: 919390 | C19: 919398 | D19: Frisco Peapod & Peas 2-in-1 Rip for Surprise Plush Squeaky Dog Toy, Small | E19: P20837 | F19: KIDS FIRST ASIA CO LTD | G19: KNGO1 | H19: 1200 | I19: 60 | J19: 0.049600804 | K19: 11100 | L19: 45992 | M19: =COUNTIF(Sheet6!C:C,Sheet2!C19) -> 0
A20: Waste Management | B20: 176623 | C20: 173773 | D20: Frisco Male Dog Wraps, Medium: 17 to 22-in waist, 50 count | E20: P000486 | F20: TIANJIN YIYI HYGIENE PRODUCTS CO. LTD | G20: KNGO1 | H20: 300 | I20: 4 | J20: 0.048506148 | K20: 300 | L20: 45992 | M20: =COUNTIF(Sheet6!C:C,Sheet2!C20) -> 0
A21: Waste Management | B21: 117279 | C21: 152569 | D21: Frisco Large Premium Dog Training & Potty Pads, 22 x 23-in, Unscented, 200 count | E21: 3722 | F21: JIANG SU ZHONG HENG PET ARTICLES JOINT-STOCK CO. | G21: KNGO1 | H21: 1500 | I21: 1 | J21: 0.048 | K21: 7323 | L21: 45992 | M21: =COUNTIF(Sheet6!C:C,Sheet2!C21) -> 0
A22: Toys | B22: 187919 | C22: 161200 | D22: Frisco Bird with Feathers Teaser Wand Cat Toy with Catnip, Purple | E22: 3755 | F22: HANGZHOU TIANYUAN PET PRODUCTS CO., LTD. | G22: MWILSON | H22: 1512 | I22: 168 | J22: 0.051768522 | K22: 3528 | L22: 45992 | M22: =COUNTIF(Sheet6!C:C,Sheet2!C22) -> 0
A23: Bowls & Feeders | B23: 231074 | C23: 204463 | D23: Frisco Saucer Cat Bowl, Gray, 1 cup, 1 count | E23: P000579 | F23: GO FETCH, LLC | G23: MWILSON | H23: 216 | I23: 1 | J23: 0.0068303331 | K23: 2424 | L23: 45992 | M23: =COUNTIF(Sheet6!C:C,Sheet2!C23) -> 0
A24: Toys | B24: 187916 | C24: 161197 | D24: Frisco Fabric Teaser Wand Cat Toy, Retro Circles | E24: P20837 | F24: KIDS FIRST ASIA CO LTD | G24: KNGO1 | H24: 1224 | I24: 72 | J24: 0.020976544 | K24: 3384 | L24: 45992 | M24: =COUNTIF(Sheet6!C:C,Sheet2!C24) -> 0
A25: Waste Management | B25: 117273 | C25: 191971 | D25: Frisco X-Large Premium Dog Training & Potty Pads, 28 x 34-in, Scented, 40 count | E25: 3722 | F25: JIANG SU ZHONG HENG PET ARTICLES JOINT-STOCK CO. | G25: KNGO1 | H25: 250 | I25: 1 | J25: 0.026881875 | K25: 4581 | L25: 45992 | M25: =COUNTIF(Sheet6!C:C,Sheet2!C25) -> 0
A26: Waste Management | B26: 253969 | C26: 227454 | D26: Frisco Giant Ultra Premium Non-Skid Dog Training & Potty Pads, 27.5 x 44-in, Unscented, 50 count | E26: 3722 | F26: JIANG SU ZHONG HENG PET ARTICLES JOINT-STOCK CO. | G26: KNGO1 | H26: 250 | I26: 1 | J26: 0.04491125 | K26: 4115 | L26: 45992 | M26: =COUNTIF(Sheet6!C:C,Sheet2!C26) -> 0
A27: Toys | B27: 173825 | C27: 146985 | D27: Frisco Monkey Plush Squeaky Dog Toy, Small/Medium | E27: P20837 | F27: KIDS FIRST ASIA CO LTD | G27: KNGO1 | H27: 1224 | I27: 36 | J27: 0.060161754 | K27: 3348 | L27: 45992 | M27: =COUNTIF(Sheet6!C:C,Sheet2!C27) -> 0
A28: Leashes, Collars & Harnesses | B28: 1016294 | C28: 1016302 | D28: Frisco Dog Tie-Out Stake | E28: B3722 | F28: JIANG SU ZHONG HENG PET ARTICLES JOINT-STOCK CO. | G28: KNGO1 | H28: 204 | I28: 6 | J28: 0.038325 | K28: 1284 | L28: 45992 | M28: =COUNTIF(Sheet6!C:C,Sheet2!C28) -> 0
A29: Litter Accessories | B29: 193012 | C29: 166310 | D29: Frisco Cat Metal Litter Scoop | E29: B3722 | F29: JIANG SU ZHONG HENG PET ARTICLES JOINT-STOCK CO. | G29: KNGO1 | H29: 960 | I29: 48 | J29: 0.05103 | K29: 960 | L29: 45992 | M29: =COUNTIF(Sheet6!C:C,Sheet2!C29) -> 0
A30: Waste Management | B30: 253966 | C30: 309796 | D30: Frisco X-Large Ultra Premium Non-Skid Dog Training & Potty Pads, 28 x 34-in, Unscented, 75 count | E30: 3722 | F30: JIANG SU ZHONG HENG PET ARTICLES JOINT-STOCK CO. | G30: KNGO1 | H30: 250 | I30: 1 | J30: 0.05535 | K30: 3718 | L30: 45992 | M30: =COUNTIF(Sheet6!C:C,Sheet2!C30) -> 0
A31: Toys | B31: 201426 | C31: 204559 | D31: Frisco Unicorn Stuffing-Free Flat Plush Squeaky Dog Toy, Purple, Medium/Large | E31: P20837 | F31: KIDS FIRST ASIA CO LTD | G31: KNGO1 | H31: 1224 | I31: 36 | J31: 0.039586539 | K31: 6660 | L31: 45992 | M31: =COUNTIF(Sheet6!C:C,Sheet2!C31) -> 0
A32: Litter Accessories | B32: 862878 | C32: 862886 | D32: Frisco Cat Litter Trapping Mat, Grey | E32: 3755 | F32: HANGZHOU TIANYUAN PET PRODUCTS CO., LTD. | G32: MWILSON | H32: 1176 | I32: 24 | J32: 0.23254596 | K32: 7608 | L32: 45992 | M32: =COUNTIF(Sheet6!C:C,Sheet2!C32) -> 0
A33: Waste Management | B33: 176623 | C33: 173774 | D33: Frisco Disposable Male Dog Wraps, Small, 30 count | E33: P000486 | F33: TIANJIN YIYI HYGIENE PRODUCTS CO. LTD | G33: KNGO1 | H33: 300 | I33: 6 | J33: 0.034409524 | K33: 804 | L33: 45992 | M33: =COUNTIF(Sheet6!C:C,Sheet2!C33) -> 0
A34: Leashes, Collars & Harnesses | B34: 193136 | C34: 984598 | D34: Frisco Tie Out Cable, 40-ft | E34: B3722 | F34: JIANG SU ZHONG HENG PET ARTICLES JOINT-STOCK CO. | G34: KNGO1 | H34: 200 | I34: 4 | J34: 0.01204125 | K34: 1004 | L34: 45992 | M34: =COUNTIF(Sheet6!C:C,Sheet2!C34) -> 0
A35: Toys | B35: 179623 | C35: 152846 | D35: Frisco Colorful Fetch Squeaky Tennis Ball Dog Toy, Medium, 3 count | E35: P20837 | F35: KIDS FIRST ASIA CO LTD | G35: KNGO1 | H35: 3024 | I35: 48 | J35: 0.045920074 | K35: 3120 | L35: 45992 | M35: =COUNTIF(Sheet6!C:C,Sheet2!C35) -> 0
A36: Toys | B36: 1329014 | C36: 1329022 | D36: Frisco Capybara Plush Squeaky Dog Toy, Small/Medium | E36: 3755 | F36: HANGZHOU TIANYUAN PET PRODUCTS CO., LTD. | G36: MWILSON | H36: 1536 | I36: 48 | J36: 0.038150039 | K36: 15312 | L36: 45992 | M36: =COUNTIF(Sheet6!C:C,Sheet2!C36) -> 0
A37: Toys | B37: 187914 | C37: 161194 | D37: Frisco Cardboard & Wire Teaser Cat Toy | E37: 3755 | F37: HANGZHOU TIANYUAN PET PRODUCTS CO., LTD. | G37: MWILSON | H37: 1536 | I37: 256 | J37: 0.055473115 | K37: 2048 | L37: 45992 | M37: =COUNTIF(Sheet6!C:C,Sheet2!C37) -> 0
A38: Waste Management | B38: 162702 | C38: 135717 | D38: Frisco Refill Dog Poop Bags, Scented, 270 count | E38: 3722 | F38: JIANG SU ZHONG HENG PET ARTICLES JOINT-STOCK CO. | G38: KNGO1 | H38: 504 | I38: 24 | J38: 0.04122625 | K38: 3552 | L38: 45992 | M38: =COUNTIF(Sheet6!C:C,Sheet2!C38) -> 0
A39: Toys | B39: 290861 | C39: 264424 | D39: Frisco Birthday Volcano & Dinosaurs Hide & Seek Puzzle Plush Squeaky Dog Toy, Small/Medium | E39: P20837 | F39: KIDS FIRST ASIA CO LTD | G39: KNGO1 | H39: 1200 | I39: 12 | J39: 0.10440304 | K39: 9060 | L39: 45992 | M39: =COUNTIF(Sheet6!C:C,Sheet2!C39) -> 0
A40: Waste Management | B40: 193036 | C40: 166334 | D40: Frisco Rake & Spade Set with Dustpan, Small | E40: B3722 | F40: JIANG SU ZHONG HENG PET ARTICLES JOINT-STOCK CO. | G40: KNGO1 | H40: 102 | I40: 6 | J40: 0.034621375 | K40: 546 | L40: 45992 | M40: =COUNTIF(Sheet6!C:C,Sheet2!C40) -> 0
...

Sheet Sheet3
A1: Toys | B1: 343211 | C1: 316929 | D1: Frisco Realistic Opossum Plush Squeaky Dog Toy, Medium/Large | E1: P18936 | F1: PETPARTY PRODUCTS CO., LTD | G1: MWILSON | H1: 1512 | I1: 36 | J1: 0.07308 | K1: 7380 | L1: 45992 | M1: =COUNTIF(Sheet6!C:C,Sheet3!C1) -> 0

Sheet Sheet6
A1: 89539 | B1: 252045 | C1: Disco | F1: Code | G1: vendor_name | H1: vendor_purchaser_code
A2: 89538 | B2: 252043 | C2: 1000089185 | F2: P27093 | G2: SPORTPET DESIGNS LLC - PL | H2: KNGO1
A3: 316929 | B3: 739686 | C3: 1000089179 | F3: P20837 | G3: KIDS FIRST ASIA CO LTD | H3: KNGO1
A4: 98763 | B4: 1054942 | C4: 1000089173 | F4: P18545 | G4: SUPER DESIGN MANUFACTURE CO ., LTD ZHUHAI | H4: MWILSON
A5: 148195 | B5: 1054950 | C5: 1000089167 | F5: P000486 | G5: TIANJIN YIYI HYGIENE PRODUCTS CO. LTD | H5: KNGO1
A6: 148196 | B6: 1054966 | C6: 1000089155 | F6: B3722 | G6: CAMBODIA JIANG SU ZHONG HENG PET ARTICLES JOINT-STOCK CO., | H6: KNGO1
A7: 156782 | B7: 1054974 | C7: 1000089143 | F7: 3722 | G7: CAMBODIA JIANG SU ZHONG HENG PET ARTICLES JOINT-STOCK CO., | H7: KNGO1
A8: 236547 | B8: 1054982 | C8: 1000089137 | F8: 3722 | G8: JIANG SU ZHONG HENG PET ARTICLES JOINT-STOCK CO. | H8: KNGO1
A9: 214369 | B9: 1055086 | C9: 1000089131 | F9: 3755 | G9: HANGZHOU TIANYUAN PET PRODUCTS CO., LTD. | H9: MWILSON
A10: 252557 | B10: 1055214 | C10: 1000089125 | F10: P000579 | G10: GO FETCH, LLC | H10: MWILSON
A11: 221968 | B11: 1055254 | C11: 1000089119 | F11: B3722 | G11: JIANG SU ZHONG HENG PET ARTICLES JOINT-STOCK CO. | H11: KNGO1
A12: 232097 | B12: 1055262 | C12: 1000089113 | F12: 7701 | G12: TIANJIN QINGQUAN PET PRODUCTS CO. LTD | H12: MWILSON
A13: 236541 | B13: 1055270 | C13: 1000089107 | F13: P26130 | G13: CAITEC INC - PL | H13: MWILSON
A14: 250607 | B14: 1055278 | C14: 1000089059 | F14: P18120 | G14: NINGBO KONY METAL PRODUCTS CO LTD | H14: MWILSON
A15: 353469 | B15: 1055294 | C15: 1000089053 | F15: P19403 | G15: SHANDONG DONGYANGTAI HANDICRAFTS CO.,LTD | H15: MWILSON
A16: 986910 | B16: 1055302 | C16: 1000089035 | F16: P000544 | G16: SHANGHAI SENFUL CO LTD | H16: MWILSON
A17: 1358014 | B17: 1055614 | C17: 1000089029 | F17: 5223 | G17: Mundosteel International Enterprises Ltd | H17: KNGO1
A18: 1445006 | B18: 1055622 | C18: 1000089017 | F18: B000064 | G18: PM&J LLC - DIRECT IMPORT | H18: KNGO1
A19: 1475206 | B19: 1055638 | C19: 1000089011 | F19: P19684 | G19: BENCHMARK HOME PRODUCTS(H.K.). LIMITED | H19: MWILSON
A20: 1475214 | B20: 1055646 | C20: 1000089005 | F20: B3722 | G20: Cambodia JIANG SU ZHONG HENG PET ARTICLES JOINT-STOCK CO. | H20: KNGO1
A21: 1475190 | B21: 1055654 | C21: 1256870 | F21: P18360 | G21: PETENGREAT CO LTD | H21: KNGO1
A22: 1475198 | B22: 1328942 | C22: 1096934 | F22: P24388 | G22: BEST RUN TECHNOLOGY CO LTD - PL | H22: MWILSON
A23: 312064 | B23: 152838 | C23: 1096926 | F23: P19360 | G23: FORTUNATE PTE. LTD. | H23: MWILSON
A24: 312070 | B24: 152840 | C24: 1096902 | F24: B000164 | G24: PM&J LLC | H24: KNGO1
A25: 608878 | B25: 152844 | C25: 1096894 | F25: B000035 | G25: COASTAL PET PRODUCTS, INC. - PRIVATE LABEL CHINA | H25: MWILSON
A26: 876246 | B26: 152848 | C26: 1096886 | F26: P000398 | G26: TANGSHAN KANGBEI PET PRODUCTS CO. LTD | H26: MWILSON
A27: 876366 | B27: 154412 | C27: 1096878 | F27: B3755 | G27: HANGZHOU TIANYUAN PET PRODUCTS CO., LTD | H27: MWILSON
A28: 876270 | B28: 154413 | C28: 1096870 | F28: B3755 | G28: HANGZHOU TIANYUAN PET PRODUCTS CO., LTD.(Cambodia) | H28: MWILSON
A29: 876238 | B29: 174774 | C29: 1096862 | F29: P000161 | G29: PM&J LLC | H29: KNGO1
... A34: 876406 | B34: 247980 | C34: 1096734 | F34: P20858 | G34: MILES HOME PRODUCTS CO LTD | H34: KNGO1
A35: 874206 | B35: 247981 | C35: 1086246
A36: 1329294 | B36: 247977 | C36: 1086222
A37: 1329278 | B37: 247978 | C37: 1086134
A38: 1330334 | B38: 714406 | C38: 1086110
A39: 1330350 | B39: 363848 | C39: 1072294
A40: 1330318 | B40: 1093822 | C40: 1072286
A41: 1330566 | B41: 708990 | C41: 1072086
A42: 876006 | B42: 215566 | C42: 1072078
A43: 1329270 | B43: 268132 | C43: 1072070
A44: 1330558 | B44: 706854 | C44: 1071974
...

Sheet Sheet1
A1: Code | B1: vendor_name
A2: 3722 | B2: JIANG SU ZHONG HENG PET ARTICLES JOINT-STOCK CO. | C2: SENT | D2: Placed
A3: B3722 | B3: JIANG SU ZHONG HENG PET ARTICLES JOINT-STOCK CO. | C3: SENT | D3: Placed
A4: P000486 | B4: TIANJIN YIYI HYGIENE PRODUCTS CO. LTD | C4: SENt | D4: Placed
A5: P20837 | B5: KIDS FIRST ASIA CO LTD | C5: SENT | D5: Placed
A6: P25855 | B6: TECHLINK PETS INTERNATIONAL LIMITED
A7: P27093 | B7: SPORTPET DESIGNS LLC - PL | C7: SENt | D7: Waiting
J12: RS41722391 | K12: =_xlfn.TEXTJOIN(",",TRUE,J12:J19) -> RS41722391,RS41722393,RS41722394,RS41722395,RS41722405,RS41722406,RS41722408,RS41722410
J13: RS41722393
J14: RS41722394
J15: RS41722395
J16: RS41722405
J17: RS41722406
J18: RS41722408
J19: RS41722410

Sheet TOADD
A1: Toys | B1: Chew Toys | C1: Dog | D1: Toys | E1: Toys | F1: 1816134 | G1: 1816142 | H1: Frisco Chocolate Dipped Strawberry Rubber Chew Dog Toy for Extreme Chewers, Small/Medium | K1: #N/A | N1: =_xlfn.TEXTJOIN(",",TRUE,G1:G12) -> 1816142,1816150,1816190,1816270,1816222,1816238,1816246,1816166,1816174,1816214,1816198,1816262
A2: Toys | B2: Chew Toys | C2: Dog | D2: Toys | E2: Toys | F2: 1816134 | G2: 1816150 | H2: Frisco Chocolate Dipped Strawberry Rubber Chew Dog Toy for Extreme Chewers, Large/X-Large | K2: #N/A
A3: Toys | B3: Chew Toys | C3: Dog | D3: Toys | E3: Toys | F3: 1816182 | G3: 1816190 | H3: Frisco Ice Cream Cone Rubber Chew Dog Toy for Heavy Chewers, Small/Medium | K3: #N/A
A4: Toys | B4: Chew Toys | C4: Dog | D4: Toys | E4: Toys | F4: 1816254 | G4: 1816270 | H4: Frisco Red Panda Rubber Chew Dog Toy for Heavy Chewers, Large/X-Large | K4: #N/A
A5: Toys | B5: Chew Toys | C5: Dog | D5: Toys | E5: Toys | F5: 1816206 | G5: 1816222 | H5: Frisco Axolotl Rubber Chew Dog Toy for Heavy Chewers, Large/X-Large | K5: #N/A
A6: Toys | B6: Chew Toys | C6: Dog | D6: Toys | E6: Toys | F6: 1816230 | G6: 1816238 | H6: Frisco Capybara Rubber Chew Dog Toy for Extreme Chewers, Small/Medium | K6: #N/A
A7: Toys | B7: Chew Toys | C7: Dog | D7: Toys | E7: Toys | F7: 1816230 | G7: 1816246 | H7: Frisco Capybara Rubber Chew Dog Toy for Extreme Chewers, Large/X-Large | K7: #N/A
A8: Toys | B8: Chew Toys | C8: Dog | D8: Toys | E8: Toys | F8: 1816158 | G8: 1816166 | H8: Frisco Sandwich Cookie Rubber Chew Dog Toy for Heavy Chewers, Small/Medium | K8: #N/A
A9: Toys | B9: Chew Toys | C9: Dog | D9: Toys | E9: Toys | F9: 1816158 | G9: 1816174 | H9: Frisco Sandwich Cookie Rubber Chew Dog Toy for Heavy Chewers, Large/X-Large | K9: #N/A
A10: Toys | B10: Chew Toys | C10: Dog | D10: Toys | E10: Toys | F10: 1816206 | G10: 1816214 | H10: Frisco Axolotl Rubber Chew Dog Toy for Heavy Chewers, Small/Medium | K10: #N/A
A11: Toys | B11: Chew Toys | C11: Dog | D11: Toys | E11: Toys | F11: 1816182 | G11: 1816198 | H11: Frisco Ice Cream Cone Rubber Chew Dog Toy for Heavy Chewers, Large/X-Large | K11: #N/A
A12: Toys | B12: Chew Toys | C12: Dog | D12: Toys | E12: Toys | F12: 1816254 | G12: 1816262 | H12: Frisco Red Panda Rubber Chew Dog Toy for Heavy Chewers, Small/Medium | K12: #N/A
